Workbook

Sheet README
A1: Workbook | B1: Main_clean.xlsx — Replikation Mönch & Stein (2021) Tabelle 3 Panel A
A2: Modelle | B2: 12 Sheets: M1_h1, M1_h3, M1_h6, M1_h12, M2_h1, ..., M3_h12
A3: Summary | B3: Sheet 'Replikation_Summary' zeigt alle 12 Modelle nebeneinander mit M&S-Paper-Werten und Differenz-Spalte.
A4: Methodik | B4: OLS-Regression des durchschnittlichen Log-Excess-Returns ueber die naechsten h Monate auf die Probit-Rezessionswahrscheinlichkeit (Stufe-1-Output aus R, rekursiv geschaetzt).
A5: OOS-Start | B5: 1980-01 (siehe Kap. 4.6)
A6: Trainingsfenster | B6: Rekursiv expandierend, Start 1965-01, Ende ROW()-h (Ende-Monat-Konvention)
A7: Zielgroesse | B7: G = AVERAGE(F[t+1]:F[t+h]) — Durchschnitt, nicht Summe
A8: HAC-Lag | B8: Newey-West mit Lag L = h (R-Konvention, war frueher L = h-1)
A9: Auswertungs-Fenster | B9: Pro Sheet zwei Boxen im Summary-Block (Row 905+): links M&S-Fenster 1980-01 bis 2019-12, rechts Full-Fenster 1980-01 bis 2026-03
A11: Block-Farben
A12: OOS-Bereich

Sheet Replikation_Summary
A1: Replikation Moench & Stein (2021), Tabelle 3 Panel A - Stufe-2-Predictive-Regression
C2: M&S-Fenster (1980-01 bis 2019-12) | J2: Full-Fenster (1980-01 bis 2026-03)
A3: Spec | B3: h | C3: R²_OS Excel (%) | D3: CW-z Excel | E3: Sig Excel | F3: R²_OS M&S (%) | G3: Sig M&S | H3: Diff (pp) | J3: R²_OS Excel (%) | K3: CW-z Excel | L3: Sig Excel
A4: M1 | B4: 1 | C4: =M1_h1!B912*100 -> -0.69176823 | D4: =M1_h1!B921 -> -1.3551459 | E4: =M1_h1!B923 -> n.s. | F4: -0.83 | H4: =C4-F4 -> 0.13823177 | J4: =M1_h1!J912*100 -> -0.57688424 | K4: =M1_h1!J921 -> -1.3558391 | L4: =M1_h1!J923 -> n.s.
A5: M2 | B5: 1 | C5: =M2_h1!B912*100 -> -0.077622179 | D5: =M2_h1!B921 -> 0.2322535 | E5: =M2_h1!B923 -> n.s. | F5: 0.23 | H5: =C5-F5 -> -0.30762218 | J5: =M2_h1!J912*100 -> -0.17577206 | K5: =M2_h1!J921 -> -0.0080237925 | L5: =M2_h1!J923 -> n.s.
A6: M3 | B6: 1 | C6: =M3_h1!B912*100 -> 0.041376574 | D6: =M3_h1!B921 -> 0.51097425 | E6: =M3_h1!B923 -> n.s. | F6: 1.11 | G6: ** | H6: =C6-F6 -> -1.0686234 | J6: =M3_h1!J912*100 -> -0.25275901 | K6: =M3_h1!J921 -> -0.4237682 | L6: =M3_h1!J923 -> n.s.
A7: M1 | B7: 3 | C7: =M1_h3!B912*100 -> -0.68522188 | D7: =M1_h3!B921 -> -0.39143463 | E7: =M1_h3!B923 -> n.s. | F7: -1.38 | H7: =C7-F7 -> 0.69477812 | J7: =M1_h3!J912*100 -> -0.90817461 | K7: =M1_h3!J921 -> -0.77330742 | L7: =M1_h3!J923 -> n.s.
A8: M2 | B8: 3 | C8: =M2_h3!B912*100 -> 1.3808839 | D8: =M2_h3!B921 -> 1.9271182 | E8: =M2_h3!B923 -> ** (5%) | F8: 1.58 | G8: ** | H8: =C8-F8 -> -0.1991161 | J8: =M2_h3!J912*100 -> 0.19119895 | K8: =M2_h3!J921 -> 0.73314174 | L8: =M2_h3!J923 -> n.s.
A9: M3 | B9: 3 | C9: =M3_h3!B912*100 -> 0.86127915 | D9: =M3_h3!B921 -> 1.7300407 | E9: =M3_h3!B923 -> ** (5%) | F9: 3.09 | G9: *** | H9: =C9-F9 -> -2.2287209 | J9: =M3_h3!J912*100 -> -0.28133946 | K9: =M3_h3!J921 -> 0.18978567 | L9: =M3_h3!J923 -> n.s.
A10: M1 | B10: 6 | C10: =M1_h6!B912*100 -> 0.13020553 | D10: =M1_h6!B921 -> 0.57679709 | E10: =M1_h6!B923 -> n.s. | F10: -1.68 | H10: =C10-F10 -> 1.8102055 | J10: =M1_h6!J912*100 -> -1.2136041 | K10: =M1_h6!J921 -> -0.06604051 | L10: =M1_h6!J923 -> n.s.
A11: M2 | B11: 6 | C11: =M2_h6!B912*100 -> 2.9212978 | D11: =M2_h6!B921 -> 2.2300235 | E11: =M2_h6!B923 -> ** (5%) | F11: 1.98 | G11: ** | H11: =C11-F11 -> 0.94129782 | J11: =M2_h6!J912*100 -> -0.064707848 | K11: =M2_h6!J921 -> 0.62337238 | L11: =M2_h6!J923 -> n.s.
A12: M3 | B12: 6 | C12: =M3_h6!B912*100 -> 2.8788008 | D12: =M3_h6!B921 -> 2.6931646 | E12: =M3_h6!B923 -> *** (1%) | F12: 3.83 | G12: ** | H12: =C12-F12 -> -0.95119922 | J12: =M3_h6!J912*100 -> 0.18913175 | K12: =M3_h6!J921 -> 0.76000671 | L12: =M3_h6!J923 -> n.s.
A13: M1 | B13: 12 | C13: =M1_h12!B912*100 -> 4.7642272 | D13: =M1_h12!B921 -> 2.1889536 | E13: =M1_h12!B923 -> ** (5%) | F13: 4.21 | G13: ** | H13: =C13-F13 -> 0.55422718 | J13: =M1_h12!J912*100 -> -0.13136698 | K13: =M1_h12!J921 -> 0.91549219 | L13: =M1_h12!J923 -> n.s.
A14: M2 | B14: 12 | C14: =M2_h12!B912*100 -> 5.4711923 | D14: =M2_h12!B921 -> 2.8950008 | E14: =M2_h12!B923 -> *** (1%) | F14: 8.23 | G14: *** | H14: =C14-F14 -> -2.7588077 | J14: =M2_h12!J912*100 -> -0.11098927 | K14: =M2_h12!J921 -> 0.65629542 | L14: =M2_h12!J923 -> n.s.
A15: M3 | B15: 12 | C15: =M3_h12!B912*100 -> 8.2593593 | D15: =M3_h12!B921 -> 3.6513231 | E15: =M3_h12!B923 -> *** (1%) | F15: 9.27 | G15: *** | H15: =C15-F15 -> -1.0106407 | J15: =M3_h12!J912*100 -> 1.6438283 | K15: =M3_h12!J921 -> 1.2381258 | L15: =M3_h12!J923 -> n.s.

Sheet M1_h1
A1: date | B1: sp500_price | C1: D_12m | D1: sp500_log_total_return | E1: rfree | F1: log_equity_prem | G1: fwd_avg_log_eqprem (Y) | H1: usrec | I1: p_M1_h1 | J1: alpha | K1: beta | L1: forecast | M1: benchmark | N1: se_model | O1: se_benchmark | P1: rolling_R2_OS | Q1: clark_west_f
A2: 18718 | B2: 21.48 | C2: 1.52 | E2: 0.0011592468 | G2: =AVERAGE(F3) -> 0.047740849 | H2: 0
A3: 18748 | B3: 22.43 | C3: 1.53333 | D3: =LN((B3+C3/12)/B2) -> 0.048957672 | E3: 0.0012168233 | F3: =D3-E3 -> 0.047740849 | G3: =AVERAGE(F4) -> -0.036727777 | H3: 0
A4: 18779 | B4: 21.52 | C4: 1.54667 | D4: =LN((B4+C4/12)/B3) -> -0.035445197 | E4: 0.0012825803 | F4: =D4-E4 -> -0.036727777 | G4: =AVERAGE(F5) -> -0.021384182 | H4: 0
A5: 18809 | B5: 20.959999 | C5: 1.56 | D5: =LN((B5+C5/12)/B4) -> -0.020183805 | E5: 0.0012003766 | F5: =D5-E5 -> -0.021384182 | G5: =AVERAGE(F6) -> 0.070891819 | H5: 0
A6: 18840 | B6: 22.4 | C6: 1.54667 | D6: =LN((B6+C6/12)/B5) -> 0.072182616 | E6: 0.0012907966 | F6: =D6-E6 -> 0.070891819 | G6: =AVERAGE(F7) -> 0.042667348 | H6: 0
A7: 18871 | B7: 23.280001 | C7: 1.53333 | D7: =LN((B7+C7/12)/B6) -> 0.044007426 | E7: 0.0013400788 | F7: =D7-E7 -> 0.042667348 | G7: =AVERAGE(F8) -> 0.0032231269 | H7: 0
A8: 18901 | B8: 23.26 | C8: 1.52 | D8: =LN((B8+C8/12)/B7) -> 0.0045714168 | E8: 0.0013482899 | F8: =D8-E8 -> 0.0032231269 | G8: =AVERAGE(F9) -> -0.0097534102 | H8: 0
A9: 18932 | B9: 22.940001 | C9: 1.48333 | D9: =LN((B9+C9/12)/B8) -> -0.0084790469 | E9: 0.0012743633 | F9: =D9-E9 -> -0.0097534102 | G9: =AVERAGE(F10) -> 0.0013454142 | H9: 0
A10: 18962 | B10: 22.879999 | C10: 1.44667 | D10: =LN((B10+C10/12)/B9) -> 0.0026362108 | E10: 0.0012907966 | F10: =D10-E10 -> 0.0013454142 | G10: =AVERAGE(F11) -> 0.041661839 | H10: 0
A11: 18993 | B11: 23.77 | C11: 1.41 | D11: =LN((B11+C11/12)/B10) -> 0.043092199 | E11: 0.0014303602 | F11: =D11-E11 -> 0.041661839 | G11: =AVERAGE(F12) -> 0.01901395 | H11: 0
A12: 19024 | B12: 24.139999 | C12: 1.41333 | D12: =LN((B12+C12/12)/B11) -> 0.020312962 | E12: 0.0012990121 | F12: =D12-E12 -> 0.01901395 | G12: =AVERAGE(F13) -> -0.033346746 | H12: 0
A13: 19053 | B13: 23.26 | C13: 1.41667 | D13: =LN((B13+C13/12)/B12) -> -0.032072383 | E13: 0.0012743633 | F13: =D13-E13 -> -0.033346746 | G13: =AVERAGE(F14) -> 0.05014625 | H13: 0
A14: 19084 | B14: 24.370001 | C14: 1.42 | D14: =LN((B14+C14/12)/B13) -> 0.051461691 | E14: 0.001315441 | F14: =D14-E14 -> 0.05014625 | G14: =AVERAGE(F15) -> -0.040243515 | H14: 0
... A167: 23742 | B167: 84.75 | C167: 2.5 | D167: =LN((B167+C167/12)/B166) -> 0.0063566216 | E167: 0.0031450242 | F167: =D167-E167 -> 0.0032115974 | G167: =AVERAGE(F168) -> 0.031889951 | H167: 0
A168: 23773 | B168: 87.559998 | C168: 2.51667 | D168: =LN((B168+C168/12)/B167) -> 0.035010821 | E168: 0.0031208697 | F168: =D168-E168 -> 0.031889951 | G168: =AVERAGE(F169) -> -0.0022915007 | H168: 0 | I168: 0.15053911
A169: 23801 | B169: 87.43 | C169: 2.53333 | D169: =LN((B169+C169/12)/B168) -> 0.00092594832 | E169: 0.003217449 | F169: =D169-E169 -> -0.0022915007 | G169: =AVERAGE(F170) -> -0.015386545 | H169: 0 | I169: 0.14358644
A170: 23832 | B170: 86.160004 | C170: 2.55 | D170: =LN((B170+C170/12)/B169) -> -0.012169096 | E170: 0.003217449 | F170: =D170-E170 -> -0.015386545 | G170: =AVERAGE(F171) -> 0.032848557 | H170: 0 | I170: 0.14127427
A171: 23862 | B171: 89.110001 | C171: 2.57 | D171: =LN((B171+C171/12)/B170) -> 0.036066006 | E171: 0.003217449 | F171: =D171-E171 -> 0.032848557 | G171: =AVERAGE(F172) -> -0.0085206412 | H171: 0 | I171: 0.14016724
A172: 23893 | B172: 88.419998 | C172: 2.59 | D172: =LN((B172+C172/12)/B171) -> -0.0053353739 | E172: 0.0031852673 | F172: =D172-E172 -> -0.0085206412 | G172: =AVERAGE(F173) -> -0.050384346 | H172: 0 | I172: 0.14175701
A173: 23923 | B173: 84.120003 | C173: 2.61 | D173: =LN((B173+C173/12)/B172) -> -0.047271529 | E173: 0.0031128168 | F173: =D173-E173 -> -0.050384346 | G173: =AVERAGE(F174) -> 0.012763033 | H173: 0 | I173: 0.14550015
A174: 23954 | B174: 85.25 | C174: 2.62667 | D174: =LN((B174+C174/12)/B173) -> 0.015908057 | E174: 0.0031450242 | F174: =D174-E174 -> 0.012763033 | G174: =AVERAGE(F175) -> 0.021650874 | H174: 0 | I174: 0.14215345
A175: 23985 | B175: 87.169998 | C175: 2.64333 | D175: =LN((B175+C175/12)/B174) -> 0.024795898 | E175: 0.0031450242 | F175: =D175-E175 -> 0.021650874 | G175: =AVERAGE(F176) -> 0.030756526 | H175: 0 | I175: 0.142574
A176: 24015 | B176: 89.959999 | C176: 2.66 | D176: =LN((B176+C176/12)/B175) -> 0.03396593 | E176: 0.0032094047 | F176: =D176-E176 -> 0.030756526 | G176: =AVERAGE(F177) -> 0.026094004 | H176: 0 | I176: 0.13895399
A177: 24046 | B177: 92.419998 | C177: 2.68 | D177: =LN((B177+C177/12)/B176) -> 0.029391858 | E177: 0.0032978538 | F177: =D177-E177 -> 0.026094004 | G177: =AVERAGE(F178) -> -0.009695953 | H177: 0 | I177: 0.13069837
A178: 24076 | B178: 91.610001 | C178: 2.7 | D178: =LN((B178+C178/12)/B177) -> -0.0063498904 | E178: 0.0033460626 | F178: =D178-E178 -> -0.009695953 | G178: =AVERAGE(F179) -> 0.0077817528 | H178: 0 | I178: 0.12980291
A179: 24107 | B179: 92.43 | C179: 2.72 | D179: =LN((B179+C179/12)/B178) -> 0.011360466 | E179: 0.0035787134 | F179: =D179-E179 -> 0.0077817528 | G179: =AVERAGE(F180) -> 0.0035652406 | H179: 0 | I179: 0.11645332
... A347: 29220 | B347: 107.94 | C347: 5.65 | D347: =LN((B347+C347/12)/B346) -> 0.020980621 | E347: 0.0095188323 | F347: =D347-E347 -> 0.011461788 | G347: =AVERAGE(F348) -> 0.050688867 | H347: 0 | I347: 0.41368376
A348: 29251 | B348: 114.16 | C348: 5.7 | D348: =LN((B348+C348/12)/B347) -> 0.06017766 | E348: 0.0094887929 | F348: =D348-E348 -> 0.050688867 | G348: =AVERAGE(F349) -> -0.010314992 | H348: 0 | I348: 0.31229874 | J348: =INTERCEPT($G$168:G347,$I$168:I347) -> -0.0090737223 | K348: =SLOPE($G$168:G347,$I$168:I347) -> 0.060598082 | L348: =J348+K348*I348 -> 0.0098509822 | M348: =AVERAGE($G$168:G347) -> -0.00021130952 | N348: =(L348-G348)^2 -> 0.00040666653 | O348: =(M348-G348)^2 -> 0.00010208441 | P348: =1-AVERAGE($N$348:N348)/AVERAGE($O$348:O348) -> -2.9836302 | Q348: =O348-N348+(M348-L348)^2 -> -0.00020333241
A349: 29280 | B349: 113.66 | C349: 5.75 | D349: =LN((B349+C349/12)/B348) -> -0.00018250906 | E349: 0.010132483 | F349: =D349-E349 -> -0.010314992 | G349: =AVERAGE(F350) -> -0.11449504 | H349: 1 | I349: 0.3259893 | J349: =INTERCEPT($G$168:G348,$I$168:I348) -> -0.0087257353 | K349: =SLOPE($G$168:G348,$I$168:I348) -> 0.057476438 | L349: =J349+K349*I349 -> 0.010010969 | M349: =AVERAGE($G$168:G348) -> -0.00026713098 | N349: =(L349-G349)^2 -> 0.015501746 | O349: =(M349-G349)^2 -> 0.013048015 | P349: =1-AVERAGE($N$348:N349)/AVERAGE($O$348:O349) -> -0.20975606 | Q349: =O349-N349+(M349-L349)^2 -> -0.0023480916
A350: 29311 | B350: 102.09 | C350: 5.8 | D350: =LN((B350+C350/12)/B349) -> -0.10263361 | E350: 0.011861426 | F350: =D350-E350 -> -0.11449504 | G350: =AVERAGE(F351) -> 0.034504172 | H350: 1 | I350: 0.51141384 | J350: =INTERCEPT($G$168:G349,$I$168:I349) -> -0.0064238079 | K350: =SLOPE($G$168:G349,$I$168:I349) -> 0.037320878 | L350: =J350+K350*I350 -> 0.012662606 | M350: =AVERAGE($G$168:G349) -> -0.00089475685 | N350: =(L350-G350)^2 -> 0.00047705403 | O350: =(M350-G350)^2 -> 0.0012530842 | P350: =1-AVERAGE($N$348:N350)/AVERAGE($O$348:O350) -> -0.13762811 | Q350: =O350-N350+(M350-L350)^2 -> 0.00095983225
A351: 29341 | B351: 106.29 | C351: 5.84667 | D351: =LN((B351+C351/12)/B350) -> 0.044889899 | E351: 0.010385726 | F351: =D351-E351 -> 0.034504172 | G351: =AVERAGE(F352) -> 0.043040618 | H351: 1 | I351: 0.47501439 | J351: =INTERCEPT($G$168:G350,$I$168:I350) -> -0.0072677749 | K351: =SLOPE($G$168:G350,$I$168:I350) -> 0.043737276 | L351: =J351+K351*I351 -> 0.01350806 | M351: =AVERAGE($G$168:G350) -> -0.00070132007 | N351: =(L351-G351)^2 -> 0.00087217196 | O351: =(M351-G351)^2 -> 0.0019133571 | P351: =1-AVERAGE($N$348:N351)/AVERAGE($O$348:O351) -> -0.057677529 | Q351: =O351-N351+(M351-L351)^2 -> 0.0012430917
A352: 29372 | B352: 111.24 | C352: 5.89333 | D352: =LN((B352+C352/12)/B351) -> 0.049923953 | E352: 0.0068833355 | F352: =D352-E352 -> 0.043040618 | G352: =AVERAGE(F353) -> 0.025226138 | H352: 1 | I352: 0.11696306 | J352: =INTERCEPT($G$168:G351,$I$168:I351) -> -0.0081932111 | K352: =SLOPE($G$168:G351,$I$168:I351) -> 0.050886329 | L352: =J352+K352*I352 -> -0.0022413901 | M352: =AVERAGE($G$168:G351) -> -0.00046359215 | N352: =(L352-G352)^2 -> 0.00075446512 | O352: =(M352-G352)^2 -> 0.00065996225 | P352: =1-AVERAGE($N$348:N352)/AVERAGE($O$348:O352) -> -0.061001999 | Q352: =O352-N352+(M352-L352)^2 -> -9.13423e-05
A353: 29402 | B353: 114.24 | C353: 5.94 | D353: =LN((B353+C353/12)/B352) -> 0.030935093 | E353: 0.0057089543 | F353: =D353-E353 -> 0.025226138 | G353: =AVERAGE(F354) -> 0.060620039 | H353: 1 | I353: 0.064531532 | J353: =INTERCEPT($G$168:G352,$I$168:I352) -> -0.0079363554 | K353: =SLOPE($G$168:G352,$I$168:I352) -> 0.050171927 | L353: =J353+K353*I353 -> -0.0046986841 | M353: =AVERAGE($G$168:G352) -> -0.00032472874 | N353: =(L353-G353)^2 -> 0.0042665356 | O353: =(M353-G353)^2 -> 0.0037142648 | P353: =1-AVERAGE($N$348:N353)/AVERAGE($O$348:O353) -> -0.076742995 | Q353: =O353-N353+(M353-L353)^2 -> -0.00053313939
A354: 29433 | B354: 121.67 | C354: 5.98333 | D354: =LN((B354+C354/12)/B353) -> 0.067100652 | E354: 0.0064806124 | F354: =D354-E354 -> 0.060620039 | G354: =AVERAGE(F355) -> 0.0026065135 | H354: 1 | I354: 0.075138891 | J354: =INTERCEPT($G$168:G353,$I$168:I353) -> -0.0069476085 | K354: =SLOPE($G$168:G353,$I$168:I353) -> 0.045956363 | L354: =J354+K354*I354 -> -0.0034944983 | M354: =AVERAGE($G$168:G353) -> 2.9313007e-06 | N354: =(L354-G354)^2 -> 3.7222346e-05 | O354: =(M354-G354)^2 -> 6.7786405e-06 | P354: =1-AVERAGE($N$348:N354)/AVERAGE($O$348:O354) -> -0.078188746 | Q354: =O354-N354+(M354-L354)^2 -> -1.8211691e-05
A355: 29464 | B355: 122.38 | C355: 6.02667 | D355: =LN((B355+C355/12)/B354) -> 0.0099138869 | E355: 0.0073073733 | F355: =D355-E355 -> 0.0026065135 | G355: =AVERAGE(F356) -> 0.020699678 | H355: 0 | I355: 0.091666309 | J355: =INTERCEPT($G$168:G354,$I$168:I354) -> -0.006863357 | K355: =SLOPE($G$168:G354,$I$168:I354) -> 0.045614097 | L355: =J355+K355*I355 -> -0.0026820811 | M355: =AVERAGE($G$168:G354) -> 1.68542e-05 | N355: =(L355-G355)^2 -> 0.00054670665 | O355: =(M355-G355)^2 -> 0.0004277792 | P355: =1-AVERAGE($N$348:N355)/AVERAGE($O$348:O355) -> -0.082235071 | Q355: =O355-N355+(M355-L355)^2 -> -0.00011164321
A356: 29494 | B356: 125.46 | C356: 6.07 | D356: =LN((B356+C356/12)/B355) -> 0.028879763 | E356: 0.0081800854 | F356: =D356-E356 -> 0.020699678 | G356: =AVERAGE(F357) -> 0.010671086 | H356: 0 | I356: 0.12625903 | J356: =INTERCEPT($G$168:G355,$I$168:I355) -> -0.0065858709 | K356: =SLOPE($G$168:G355,$I$168:I355) -> 0.04459686 | L356: =J356+K356*I356 -> -0.00095511447 | M356: =AVERAGE($G$168:G355) -> 0.00012686922 | N356: =(L356-G356)^2 -> 0.00013516853 | O356: =(M356-G356)^2 -> 0.0001111805 | P356: =1-AVERAGE($N$348:N356)/AVERAGE($O$348:O356) -> -0.082934107 | Q356: =O356-N356+(M356-L356)^2 -> -2.2817341e-05
A357: 29525 | B357: 127.47 | C357: 6.1 | D357: =LN((B357+C357/12)/B356) -> 0.019874013 | E357: 0.0092029272 | F357: =D357-E357 -> 0.010671086 | G357: =AVERAGE(F358) -> 0.090318421 | H357: 0 | I357: 0.18303376 | J357: =INTERCEPT($G$168:G356,$I$168:I356) -> -0.0064931781 | K357: =SLOPE($G$168:G356,$I$168:I356) -> 0.044389545 | L357: =J357+K357*I357 -> 0.0016316073 | M357: =AVERAGE($G$168:G356) -> 0.00018265873 | N357: =(L357-G357)^2 -> 0.0078653509 | O357: =(M357-G357)^2 -> 0.0081244556 | P357: =1-AVERAGE($N$348:N357)/AVERAGE($O$348:O357) -> -0.051160653 | Q357: =O357-N357+(M357-L357)^2 -> 0.00026120416
A358: 29555 | B358: 140.52 | C358: 6.13 | D358: =LN((B358+C358/12)/B357) -> 0.10109752 | E358: 0.0107791 | F358: =D358-E358 -> 0.090318421 | G358: =AVERAGE(F359) -> -0.042760675 | H358: 0 | I358: 0.3687627 | J358: =INTERCEPT($G$168:G357,$I$168:I357) -> -0.0063465163 | K358: =SLOPE($G$168:G357,$I$168:I357) -> 0.046515625 | L358: =J358+K358*I358 -> 0.010806711 | M358: =AVERAGE($G$168:G357) -> 0.00065705747 | N358: =(L358-G358)^2 -> 0.0028694648 | O358: =(M358-G358)^2 -> 0.0018850995 | P358: =1-AVERAGE($N$348:N358)/AVERAGE($O$348:O358) -> -0.079577753 | Q358: =O358-N358+(M358-L358)^2 -> -0.00088134989
A359: 29586 | B359: 135.75999 | C359: 6.16 | D359: =LN((B359+C359/12)/B358) -> -0.030687225 | E359: 0.012073449 | F359: =D359-E359 -> -0.042760675 | G359: =AVERAGE(F360) -> -0.054570996 | H359: 0 | I359: 0.58078283 | J359: =INTERCEPT($G$168:G358,$I$168:I358) -> -0.0053686567 | K359: =SLOPE($G$168:G358,$I$168:I358) -> 0.038221197 | L359: =J359+K359*I359 -> 0.016829558 | M359: =AVERAGE($G$168:G358) -> 0.0004297395 | N359: =(L359-G359)^2 -> 0.005098039 | O359: =(M359-G359)^2 -> 0.0030250809 | P359: =1-AVERAGE($N$348:N359)/AVERAGE($O$348:O359) -> -0.13304049 | Q359: =O359-N359+(M359-L359)^2 -> -0.0018040041
...

Sheet M2_h1
A1: date | B1: sp500_price | C1: D_12m | D1: sp500_log_total_return | E1: rfree | F1: log_equity_prem | G1: fwd_avg_log_eqprem (Y) | H1: usrec | I1: p_M2_h1 | J1: alpha | K1: beta | L1: forecast | M1: benchmark | N1: se_model | O1: se_benchmark | P1: rolling_R2_OS | Q1: clark_west_f
A2: 18718 | B2: 21.48 | C2: 1.52 | E2: 0.0011592468 | G2: =AVERAGE(F3) -> 0.047740849 | H2: 0
A3: 18748 | B3: 22.43 | C3: 1.53333 | D3: =LN((B3+C3/12)/B2) -> 0.048957672 | E3: 0.0012168233 | F3: =D3-E3 -> 0.047740849 | G3: =AVERAGE(F4) -> -0.036727777 | H3: 0
A4: 18779 | B4: 21.52 | C4: 1.54667 | D4: =LN((B4+C4/12)/B3) -> -0.035445197 | E4: 0.0012825803 | F4: =D4-E4 -> -0.036727777 | G4: =AVERAGE(F5) -> -0.021384182 | H4: 0
A5: 18809 | B5: 20.959999 | C5: 1.56 | D5: =LN((B5+C5/12)/B4) -> -0.020183805 | E5: 0.0012003766 | F5: =D5-E5 -> -0.021384182 | G5: =AVERAGE(F6) -> 0.070891819 | H5: 0
A6: 18840 | B6: 22.4 | C6: 1.54667 | D6: =LN((B6+C6/12)/B5) -> 0.072182616 | E6: 0.0012907966 | F6: =D6-E6 -> 0.070891819 | G6: =AVERAGE(F7) -> 0.042667348 | H6: 0
A7: 18871 | B7: 23.280001 | C7: 1.53333 | D7: =LN((B7+C7/12)/B6) -> 0.044007426 | E7: 0.0013400788 | F7: =D7-E7 -> 0.042667348 | G7: =AVERAGE(F8) -> 0.0032231269 | H7: 0
A8: 18901 | B8: 23.26 | C8: 1.52 | D8: =LN((B8+C8/12)/B7) -> 0.0045714168 | E8: 0.0013482899 | F8: =D8-E8 -> 0.0032231269 | G8: =AVERAGE(F9) -> -0.0097534102 | H8: 0
A9: 18932 | B9: 22.940001 | C9: 1.48333 | D9: =LN((B9+C9/12)/B8) -> -0.0084790469 | E9: 0.0012743633 | F9: =D9-E9 -> -0.0097534102 | G9: =AVERAGE(F10) -> 0.0013454142 | H9: 0
A10: 18962 | B10: 22.879999 | C10: 1.44667 | D10: =LN((B10+C10/12)/B9) -> 0.0026362108 | E10: 0.0012907966 | F10: =D10-E10 -> 0.0013454142 | G10: =AVERAGE(F11) -> 0.041661839 | H10: 0
A11: 18993 | B11: 23.77 | C11: 1.41 | D11: =LN((B11+C11/12)/B10) -> 0.043092199 | E11: 0.0014303602 | F11: =D11-E11 -> 0.041661839 | G11: =AVERAGE(F12) -> 0.01901395 | H11: 0
A12: 19024 | B12: 24.139999 | C12: 1.41333 | D12: =LN((B12+C12/12)/B11) -> 0.020312962 | E12: 0.0012990121 | F12: =D12-E12 -> 0.01901395 | G12: =AVERAGE(F13) -> -0.033346746 | H12: 0
A13: 19053 | B13: 23.26 | C13: 1.41667 | D13: =LN((B13+C13/12)/B12) -> -0.032072383 | E13: 0.0012743633 | F13: =D13-E13 -> -0.033346746 | G13: =AVERAGE(F14) -> 0.05014625 | H13: 0
A14: 19084 | B14: 24.370001 | C14: 1.42 | D14: =LN((B14+C14/12)/B13) -> 0.051461691 | E14: 0.001315441 | F14: =D14-E14 -> 0.05014625 | G14: =AVERAGE(F15) -> -0.040243515 | H14: 0
... A167: 23742 | B167: 84.75 | C167: 2.5 | D167: =LN((B167+C167/12)/B166) -> 0.0063566216 | E167: 0.0031450242 | F167: =D167-E167 -> 0.0032115974 | G167: =AVERAGE(F168) -> 0.031889951 | H167: 0
A168: 23773 | B168: 87.559998 | C168: 2.51667 | D168: =LN((B168+C168/12)/B167) -> 0.035010821 | E168: 0.0031208697 | F168: =D168-E168 -> 0.031889951 | G168: =AVERAGE(F169) -> -0.0022915007 | H168: 0 | I168: 0.16103344
A169: 23801 | B169: 87.43 | C169: 2.53333 | D169: =LN((B169+C169/12)/B168) -> 0.00092594832 | E169: 0.003217449 | F169: =D169-E169 -> -0.0022915007 | G169: =AVERAGE(F170) -> -0.015386545 | H169: 0 | I169: 0.1510061
A170: 23832 | B170: 86.160004 | C170: 2.55 | D170: =LN((B170+C170/12)/B169) -> -0.012169096 | E170: 0.003217449 | F170: =D170-E170 -> -0.015386545 | G170: =AVERAGE(F171) -> 0.032848557 | H170: 0 | I170: 0.16436808
A171: 23862 | B171: 89.110001 | C171: 2.57 | D171: =LN((B171+C171/12)/B170) -> 0.036066006 | E171: 0.003217449 | F171: =D171-E171 -> 0.032848557 | G171: =AVERAGE(F172) -> -0.0085206412 | H171: 0 | I171: 0.17832776
A172: 23893 | B172: 88.419998 | C172: 2.59 | D172: =LN((B172+C172/12)/B171) -> -0.0053353739 | E172: 0.0031852673 | F172: =D172-E172 -> -0.0085206412 | G172: =AVERAGE(F173) -> -0.050384346 | H172: 0 | I172: 0.21061991
A173: 23923 | B173: 84.120003 | C173: 2.61 | D173: =LN((B173+C173/12)/B172) -> -0.047271529 | E173: 0.0031128168 | F173: =D173-E173 -> -0.050384346 | G173: =AVERAGE(F174) -> 0.012763033 | H173: 0 | I173: 0.3201656
A174: 23954 | B174: 85.25 | C174: 2.62667 | D174: =LN((B174+C174/12)/B173) -> 0.015908057 | E174: 0.0031450242 | F174: =D174-E174 -> 0.012763033 | G174: =AVERAGE(F175) -> 0.021650874 | H174: 0 | I174: 0.30089043
A175: 23985 | B175: 87.169998 | C175: 2.64333 | D175: =LN((B175+C175/12)/B174) -> 0.024795898 | E175: 0.0031450242 | F175: =D175-E175 -> 0.021650874 | G175: =AVERAGE(F176) -> 0.030756526 | H175: 0 | I175: 0.36305608
A176: 24015 | B176: 89.959999 | C176: 2.66 | D176: =LN((B176+C176/12)/B175) -> 0.03396593 | E176: 0.0032094047 | F176: =D176-E176 -> 0.030756526 | G176: =AVERAGE(F177) -> 0.026094004 | H176: 0 | I176: 0.36527601
A177: 24046 | B177: 92.419998 | C177: 2.68 | D177: =LN((B177+C177/12)/B176) -> 0.029391858 | E177: 0.0032978538 | F177: =D177-E177 -> 0.026094004 | G177: =AVERAGE(F178) -> -0.009695953 | H177: 0 | I177: 0.33608673
A178: 24076 | B178: 91.610001 | C178: 2.7 | D178: =LN((B178+C178/12)/B177) -> -0.0063498904 | E178: 0.0033460626 | F178: =D178-E178 -> -0.009695953 | G178: =AVERAGE(F179) -> 0.0077817528 | H178: 0 | I178: 0.31253513
A179: 24107 | B179: 92.43 | C179: 2.72 | D179: =LN((B179+C179/12)/B178) -> 0.011360466 | E179: 0.0035787134 | F179: =D179-E179 -> 0.0077817528 | G179: =AVERAGE(F180) -> 0.0035652406 | H179: 0 | I179: 0.22091896
... A347: 29220 | B347: 107.94 | C347: 5.65 | D347: =LN((B347+C347/12)/B346) -> 0.020980621 | E347: 0.0095188323 | F347: =D347-E347 -> 0.011461788 | G347: =AVERAGE(F348) -> 0.050688867 | H347: 0 | I347: 0.27387213
A348: 29251 | B348: 114.16 | C348: 5.7 | D348: =LN((B348+C348/12)/B347) -> 0.06017766 | E348: 0.0094887929 | F348: =D348-E348 -> 0.050688867 | G348: =AVERAGE(F349) -> -0.010314992 | H348: 0 | I348: 0.38563971 | J348: =INTERCEPT($G$168:G347,$I$168:I347) -> -0.0020561242 | K348: =SLOPE($G$168:G347,$I$168:I347) -> 0.0091917215 | L348: =J348+K348*I348 -> 0.0014885687 | M348: =AVERAGE($G$168:G347) -> -0.00021130952 | N348: =(L348-G348)^2 -> 0.00013932405 | O348: =(M348-G348)^2 -> 0.00010208441 | P348: =1-AVERAGE($N$348:N348)/AVERAGE($O$348:O348) -> -0.3647927 | Q348: =O348-N348+(M348-L348)^2 -> -3.435006e-05
A349: 29280 | B349: 113.66 | C349: 5.75 | D349: =LN((B349+C349/12)/B348) -> -0.00018250906 | E349: 0.010132483 | F349: =D349-E349 -> -0.010314992 | G349: =AVERAGE(F350) -> -0.11449504 | H349: 1 | I349: 0.44390198 | J349: =INTERCEPT($G$168:G348,$I$168:I348) -> -0.0020733691 | K349: =SLOPE($G$168:G348,$I$168:I348) -> 0.0089539328 | L349: =J349+K349*I349 -> 0.0019012994 | M349: =AVERAGE($G$168:G348) -> -0.00026713098 | N349: =(L349-G349)^2 -> 0.013548108 | O349: =(M349-G349)^2 -> 0.013048015 | P349: =1-AVERAGE($N$348:N349)/AVERAGE($O$348:O349) -> -0.040861461 | Q349: =O349-N349+(M349-L349)^2 -> -0.00049539054
A350: 29311 | B350: 102.09 | C350: 5.8 | D350: =LN((B350+C350/12)/B349) -> -0.10263361 | E350: 0.011861426 | F350: =D350-E350 -> -0.11449504 | G350: =AVERAGE(F351) -> 0.034504172 | H350: 1 | I350: 0.48943814 | J350: =INTERCEPT($G$168:G349,$I$168:I349) -> -0.002093337 | K350: =SLOPE($G$168:G349,$I$168:I349) -> 0.0059026983 | L350: =J350+K350*I350 -> 0.00079566867 | M350: =AVERAGE($G$168:G349) -> -0.00089475685 | N350: =(L350-G350)^2 -> 0.0011362632 | O350: =(M350-G350)^2 -> 0.0012530842 | P350: =1-AVERAGE($N$348:N350)/AVERAGE($O$348:O350) -> -0.029195719 | Q350: =O350-N350+(M350-L350)^2 -> 0.00011967851
A351: 29341 | B351: 106.29 | C351: 5.84667 | D351: =LN((B351+C351/12)/B350) -> 0.044889899 | E351: 0.010385726 | F351: =D351-E351 -> 0.034504172 | G351: =AVERAGE(F352) -> 0.043040618 | H351: 1 | I351: 0.70092265 | J351: =INTERCEPT($G$168:G350,$I$168:I350) -> -0.0021210784 | K351: =SLOPE($G$168:G350,$I$168:I350) -> 0.00693847 | L351: =J351+K351*I351 -> 0.0027422523 | M351: =AVERAGE($G$168:G350) -> -0.00070132007 | N351: =(L351-G351)^2 -> 0.0016239583 | O351: =(M351-G351)^2 -> 0.0019133571 | P351: =1-AVERAGE($N$348:N351)/AVERAGE($O$348:O351) -> -0.0080355535 | Q351: =O351-N351+(M351-L351)^2 -> 0.00030125706
A352: 29372 | B352: 111.24 | C352: 5.89333 | D352: =LN((B352+C352/12)/B351) -> 0.049923953 | E352: 0.0068833355 | F352: =D352-E352 -> 0.043040618 | G352: =AVERAGE(F353) -> 0.025226138 | H352: 1 | I352: 0.98491923 | J352: =INTERCEPT($G$168:G351,$I$168:I351) -> -0.0023355108 | K352: =SLOPE($G$168:G351,$I$168:I351) -> 0.009029191 | L352: =J352+K352*I352 -> 0.006557513 | M352: =AVERAGE($G$168:G351) -> -0.00046359215 | N352: =(L352-G352)^2 -> 0.00034851757 | O352: =(M352-G352)^2 -> 0.00065996225 | P352: =1-AVERAGE($N$348:N352)/AVERAGE($O$348:O352) -> 0.010622461 | Q352: =O352-N352+(M352-L352)^2 -> 0.0003607406
A353: 29402 | B353: 114.24 | C353: 5.94 | D353: =LN((B353+C353/12)/B352) -> 0.030935093 | E353: 0.0057089543 | F353: =D353-E353 -> 0.025226138 | G353: =AVERAGE(F354) -> 0.060620039 | H353: 1 | I353: 0.99729629 | J353: =INTERCEPT($G$168:G352,$I$168:I352) -> -0.0025365116 | K353: =SLOPE($G$168:G352,$I$168:I352) -> 0.010456525 | L353: =J353+K353*I353 -> 0.0078917422 | M353: =AVERAGE($G$168:G352) -> -0.00032472874 | N353: =(L353-G353)^2 -> 0.0027802733 | O353: =(M353-G353)^2 -> 0.0037142648 | P353: =1-AVERAGE($N$348:N353)/AVERAGE($O$348:O353) -> 0.053856081 | Q353: =O353-N353+(M353-L353)^2 -> 0.0010015018
A354: 29433 | B354: 121.67 | C354: 5.98333 | D354: =LN((B354+C354/12)/B353) -> 0.067100652 | E354: 0.0064806124 | F354: =D354-E354 -> 0.060620039 | G354: =AVERAGE(F355) -> 0.0026065135 | H354: 1 | I354: 0.92326072 | J354: =INTERCEPT($G$168:G353,$I$168:I353) -> -0.0030816503 | K354: =SLOPE($G$168:G353,$I$168:I353) -> 0.014297258 | L354: =J354+K354*I354 -> 0.010118447 | M354: =AVERAGE($G$168:G353) -> 2.9313007e-06 | N354: =(L354-G354)^2 -> 5.6429137e-05 | O354: =(M354-G354)^2 -> 6.7786405e-06 | P354: =1-AVERAGE($N$348:N354)/AVERAGE($O$348:O354) -> 0.051439584 | Q354: =O354-N354+(M354-L354)^2 -> 5.2673152e-05
A355: 29464 | B355: 122.38 | C355: 6.02667 | D355: =LN((B355+C355/12)/B354) -> 0.0099138869 | E355: 0.0073073733 | F355: =D355-E355 -> 0.0026065135 | G355: =AVERAGE(F356) -> 0.020699678 | H355: 0 | I355: 0.93022635 | J355: =INTERCEPT($G$168:G354,$I$168:I354) -> -0.0030184578 | K355: =SLOPE($G$168:G354,$I$168:I354) -> 0.013826419 | L355: =J355+K355*I355 -> 0.0098432415 | M355: =AVERAGE($G$168:G354) -> 1.68542e-05 | N355: =(L355-G355)^2 -> 0.00011786221 | O355: =(M355-G355)^2 -> 0.0004277792 | P355: =1-AVERAGE($N$348:N355)/AVERAGE($O$348:O355) -> 0.065068354 | Q355: =O355-N355+(M355-L355)^2 -> 0.00040647487
A356: 29494 | B356: 125.46 | C356: 6.07 | D356: =LN((B356+C356/12)/B355) -> 0.028879763 | E356: 0.0081800854 | F356: =D356-E356 -> 0.020699678 | G356: =AVERAGE(F357) -> 0.010671086 | H356: 0 | I356: 0.99971518 | J356: =INTERCEPT($G$168:G355,$I$168:I355) -> -0.0031068164 | K356: =SLOPE($G$168:G355,$I$168:I355) -> 0.014480691 | L356: =J356+K356*I356 -> 0.01136975 | M356: =AVERAGE($G$168:G355) -> 0.00012686922 | N356: =(L356-G356)^2 -> 4.8813184e-07 | O356: =(M356-G356)^2 -> 0.0001111805 | P356: =1-AVERAGE($N$348:N356)/AVERAGE($O$348:O356) -> 0.069940061 | Q356: =O356-N356+(M356-L356)^2 -> 0.00023709474
A357: 29525 | B357: 127.47 | C357: 6.1 | D357: =LN((B357+C357/12)/B356) -> 0.019874013 | E357: 0.0092029272 | F357: =D357-E357 -> 0.010671086 | G357: =AVERAGE(F358) -> 0.090318421 | H357: 0 | I357: 0.99697417 | J357: =INTERCEPT($G$168:G356,$I$168:I356) -> -0.0031005606 | K357: =SLOPE($G$168:G356,$I$168:I356) -> 0.014436928 | L357: =J357+K357*I357 -> 0.011292684 | M357: =AVERAGE($G$168:G356) -> 0.00018265873 | N357: =(L357-G357)^2 -> 0.0062450671 | O357: =(M357-G357)^2 -> 0.0081244556 | P357: =1-AVERAGE($N$348:N357)/AVERAGE($O$348:O357) -> 0.11459676 | Q357: =O357-N357+(M357-L357)^2 -> 0.0020028212
A358: 29555 | B358: 140.52 | C358: 6.13 | D358: =LN((B358+C358/12)/B357) -> 0.10109752 | E358: 0.0107791 | F358: =D358-E358 -> 0.090318421 | G358: =AVERAGE(F359) -> -0.042760675 | H358: 0 | I358: 0.0016295162 | J358: =INTERCEPT($G$168:G357,$I$168:I357) -> -0.0037685386 | K358: =SLOPE($G$168:G357,$I$168:I357) -> 0.019119653 | L358: =J358+K358*I358 -> -0.0037373829 | M358: =AVERAGE($G$168:G357) -> 0.00065705747 | N358: =(L358-G358)^2 -> 0.0015228173 | O358: =(M358-G358)^2 -> 0.0018850995 | P358: =1-AVERAGE($N$348:N358)/AVERAGE($O$348:O358) -> 0.11927754 | Q358: =O358-N358+(M358-L358)^2 -> 0.00038159327
A359: 29586 | B359: 135.75999 | C359: 6.16 | D359: =LN((B359+C359/12)/B358) -> -0.030687225 | E359: 0.012073449 | F359: =D359-E359 -> -0.042760675 | G359: =AVERAGE(F360) -> -0.054570996 | H359: 0 | I359: 3.0767045e-07 | J359: =INTERCEPT($G$168:G358,$I$168:I358) -> -0.0041312342 | K359: =SLOPE($G$168:G358,$I$168:I358) -> 0.019807491 | L359: =J359+K359*I359 -> -0.0041312281 | M359: =AVERAGE($G$168:G358) -> 0.0004297395 | N359: =(L359-G359)^2 -> 0.0025441702 | O359: =(M359-G359)^2 -> 0.0030250809 | P359: =1-AVERAGE($N$348:N359)/AVERAGE($O$348:O359) -> 0.12278155 | Q359: =O359-N359+(M359-L359)^2 -> 0.00050171314
...

Sheet M3_h1
A1: date | B1: sp500_price | C1: D_12m | D1: sp500_log_total_return | E1: rfree | F1: log_equity_prem | G1: fwd_avg_log_eqprem (Y) | H1: usrec | I1: p_M3_h1 | J1: alpha | K1: beta | L1: forecast | M1: benchmark | N1: se_model | O1: se_benchmark | P1: rolling_R2_OS | Q1: clark_west_f
A2: 18718 | B2: 21.48 | C2: 1.52 | E2: 0.0011592468 | G2: =AVERAGE(F3) -> 0.047740849 | H2: 0
A3: 18748 | B3: 22.43 | C3: 1.53333 | D3: =LN((B3+C3/12)/B2) -> 0.048957672 | E3: 0.0012168233 | F3: =D3-E3 -> 0.047740849 | G3: =AVERAGE(F4) -> -0.036727777 | H3: 0
A4: 18779 | B4: 21.52 | C4: 1.54667 | D4: =LN((B4+C4/12)/B3) -> -0.035445197 | E4: 0.0012825803 | F4: =D4-E4 -> -0.036727777 | G4: =AVERAGE(F5) -> -0.021384182 | H4: 0
A5: 18809 | B5: 20.959999 | C5: 1.56 | D5: =LN((B5+C5/12)/B4) -> -0.020183805 | E5: 0.0012003766 | F5: =D5-E5 -> -0.021384182 | G5: =AVERAGE(F6) -> 0.070891819 | H5: 0
A6: 18840 | B6: 22.4 | C6: 1.54667 | D6: =LN((B6+C6/12)/B5) -> 0.072182616 | E6: 0.0012907966 | F6: =D6-E6 -> 0.070891819 | G6: =AVERAGE(F7) -> 0.042667348 | H6: 0
A7: 18871 | B7: 23.280001 | C7: 1.53333 | D7: =LN((B7+C7/12)/B6) -> 0.044007426 | E7: 0.0013400788 | F7: =D7-E7 -> 0.042667348 | G7: =AVERAGE(F8) -> 0.0032231269 | H7: 0
A8: 18901 | B8: 23.26 | C8: 1.52 | D8: =LN((B8+C8/12)/B7) -> 0.0045714168 | E8: 0.0013482899 | F8: =D8-E8 -> 0.0032231269 | G8: =AVERAGE(F9) -> -0.0097534102 | H8: 0
A9: 18932 | B9: 22.940001 | C9: 1.48333 | D9: =LN((B9+C9/12)/B8) -> -0.0084790469 | E9: 0.0012743633 | F9: =D9-E9 -> -0.0097534102 | G9: =AVERAGE(F10) -> 0.0013454142 | H9: 0
A10: 18962 | B10: 22.879999 | C10: 1.44667 | D10: =LN((B10+C10/12)/B9) -> 0.0026362108 | E10: 0.0012907966 | F10: =D10-E10 -> 0.0013454142 | G10: =AVERAGE(F11) -> 0.041661839 | H10: 0
A11: 18993 | B11: 23.77 | C11: 1.41 | D11: =LN((B11+C11/12)/B10) -> 0.043092199 | E11: 0.0014303602 | F11: =D11-E11 -> 0.041661839 | G11: =AVERAGE(F12) -> 0.01901395 | H11: 0
A12: 19024 | B12: 24.139999 | C12: 1.41333 | D12: =LN((B12+C12/12)/B11) -> 0.020312962 | E12: 0.0012990121 | F12: =D12-E12 -> 0.01901395 | G12: =AVERAGE(F13) -> -0.033346746 | H12: 0
A13: 19053 | B13: 23.26 | C13: 1.41667 | D13: =LN((B13+C13/12)/B12) -> -0.032072383 | E13: 0.0012743633 | F13: =D13-E13 -> -0.033346746 | G13: =AVERAGE(F14) -> 0.05014625 | H13: 0
A14: 19084 | B14: 24.370001 | C14: 1.42 | D14: =LN((B14+C14/12)/B13) -> 0.051461691 | E14: 0.001315441 | F14: =D14-E14 -> 0.05014625 | G14: =AVERAGE(F15) -> -0.040243515 | H14: 0
... A167: 23742 | B167: 84.75 | C167: 2.5 | D167: =LN((B167+C167/12)/B166) -> 0.0063566216 | E167: 0.0031450242 | F167: =D167-E167 -> 0.0032115974 | G167: =AVERAGE(F168) -> 0.031889951 | H167: 0
A168: 23773 | B168: 87.559998 | C168: 2.51667 | D168: =LN((B168+C168/12)/B167) -> 0.035010821 | E168: 0.0031208697 | F168: =D168-E168 -> 0.031889951 | G168: =AVERAGE(F169) -> -0.0022915007 | H168: 0 | I168: 0.24198867
A169: 23801 | B169: 87.43 | C169: 2.53333 | D169: =LN((B169+C169/12)/B168) -> 0.00092594832 | E169: 0.003217449 | F169: =D169-E169 -> -0.0022915007 | G169: =AVERAGE(F170) -> -0.015386545 | H169: 0 | I169: 0.25977011
A170: 23832 | B170: 86.160004 | C170: 2.55 | D170: =LN((B170+C170/12)/B169) -> -0.012169096 | E170: 0.003217449 | F170: =D170-E170 -> -0.015386545 | G170: =AVERAGE(F171) -> 0.032848557 | H170: 0 | I170: 0.28093144
A171: 23862 | B171: 89.110001 | C171: 2.57 | D171: =LN((B171+C171/12)/B170) -> 0.036066006 | E171: 0.003217449 | F171: =D171-E171 -> 0.032848557 | G171: =AVERAGE(F172) -> -0.0085206412 | H171: 0 | I171: 0.30340096
A172: 23893 | B172: 88.419998 | C172: 2.59 | D172: =LN((B172+C172/12)/B171) -> -0.0053353739 | E172: 0.0031852673 | F172: =D172-E172 -> -0.0085206412 | G172: =AVERAGE(F173) -> -0.050384346 | H172: 0 | I172: 0.33008834
A173: 23923 | B173: 84.120003 | C173: 2.61 | D173: =LN((B173+C173/12)/B172) -> -0.047271529 | E173: 0.0031128168 | F173: =D173-E173 -> -0.050384346 | G173: =AVERAGE(F174) -> 0.012763033 | H173: 0 | I173: 0.35962773
A174: 23954 | B174: 85.25 | C174: 2.62667 | D174: =LN((B174+C174/12)/B173) -> 0.015908057 | E174: 0.0031450242 | F174: =D174-E174 -> 0.012763033 | G174: =AVERAGE(F175) -> 0.021650874 | H174: 0 | I174: 0.37919074
A175: 23985 | B175: 87.169998 | C175: 2.64333 | D175: =LN((B175+C175/12)/B174) -> 0.024795898 | E175: 0.0031450242 | F175: =D175-E175 -> 0.021650874 | G175: =AVERAGE(F176) -> 0.030756526 | H175: 0 | I175: 0.40332909
A176: 24015 | B176: 89.959999 | C176: 2.66 | D176: =LN((B176+C176/12)/B175) -> 0.03396593 | E176: 0.0032094047 | F176: =D176-E176 -> 0.030756526 | G176: =AVERAGE(F177) -> 0.026094004 | H176: 0 | I176: 0.42332509
A177: 24046 | B177: 92.419998 | C177: 2.68 | D177: =LN((B177+C177/12)/B176) -> 0.029391858 | E177: 0.0032978538 | F177: =D177-E177 -> 0.026094004 | G177: =AVERAGE(F178) -> -0.009695953 | H177: 0 | I177: 0.44021495
A178: 24076 | B178: 91.610001 | C178: 2.7 | D178: =LN((B178+C178/12)/B177) -> -0.0063498904 | E178: 0.0033460626 | F178: =D178-E178 -> -0.009695953 | G178: =AVERAGE(F179) -> 0.0077817528 | H178: 0 | I178: 0.46532051
A179: 24107 | B179: 92.43 | C179: 2.72 | D179: =LN((B179+C179/12)/B178) -> 0.011360466 | E179: 0.0035787134 | F179: =D179-E179 -> 0.0077817528 | G179: =AVERAGE(F180) -> 0.0035652406 | H179: 0 | I179: 0.47560984
... A347: 29220 | B347: 107.94 | C347: 5.65 | D347: =LN((B347+C347/12)/B346) -> 0.020980621 | E347: 0.0095188323 | F347: =D347-E347 -> 0.011461788 | G347: =AVERAGE(F348) -> 0.050688867 | H347: 0 | I347: 0.33156945
A348: 29251 | B348: 114.16 | C348: 5.7 | D348: =LN((B348+C348/12)/B347) -> 0.06017766 | E348: 0.0094887929 | F348: =D348-E348 -> 0.050688867 | G348: =AVERAGE(F349) -> -0.010314992 | H348: 0 | I348: 0.27019119 | J348: =INTERCEPT($G$168:G347,$I$168:I347) -> -0.0048231633 | K348: =SLOPE($G$168:G347,$I$168:I347) -> 0.018560924 | L348: =J348+K348*I348 -> 0.00019183493 | M348: =AVERAGE($G$168:G347) -> -0.00021130952 | N348: =(L348-G348)^2 -> 0.00011039342 | O348: =(M348-G348)^2 -> 0.00010208441 | P348: =1-AVERAGE($N$348:N348)/AVERAGE($O$348:O348) -> -0.081393556 | Q348: =O348-N348+(M348-L348)^2 -> -8.1464875e-06
A349: 29280 | B349: 113.66 | C349: 5.75 | D349: =LN((B349+C349/12)/B348) -> -0.00018250906 | E349: 0.010132483 | F349: =D349-E349 -> -0.010314992 | G349: =AVERAGE(F350) -> -0.11449504 | H349: 1 | I349: 0.29771292 | J349: =INTERCEPT($G$168:G348,$I$168:I348) -> -0.0048748236 | K349: =SLOPE($G$168:G348,$I$168:I348) -> 0.018535225 | L349: =J349+K349*I349 -> 0.00064335246 | M349: =AVERAGE($G$168:G348) -> -0.00026713098 | N349: =(L349-G349)^2 -> 0.013256849 | O349: =(M349-G349)^2 -> 0.013048015 | P349: =1-AVERAGE($N$348:N349)/AVERAGE($O$348:O349) -> -0.016512668 | Q349: =O349-N349+(M349-L349)^2 -> -0.00020800524
A350: 29311 | B350: 102.09 | C350: 5.8 | D350: =LN((B350+C350/12)/B349) -> -0.10263361 | E350: 0.011861426 | F350: =D350-E350 -> -0.11449504 | G350: =AVERAGE(F351) -> 0.034504172 | H350: 1 | I350: 0.47170683 | J350: =INTERCEPT($G$168:G349,$I$168:I349) -> -0.0053489913 | K350: =SLOPE($G$168:G349,$I$168:I349) -> 0.017898481 | L350: =J350+K350*I350 -> 0.0030938445 | M350: =AVERAGE($G$168:G349) -> -0.00089475685 | N350: =(L350-G350)^2 -> 0.0009866087 | O350: =(M350-G350)^2 -> 0.0012530842 | P350: =1-AVERAGE($N$348:N350)/AVERAGE($O$348:O350) -> 0.0034250944 | Q350: =O350-N350+(M350-L350)^2 -> 0.00028238443
A351: 29341 | B351: 106.29 | C351: 5.84667 | D351: =LN((B351+C351/12)/B350) -> 0.044889899 | E351: 0.010385726 | F351: =D351-E351 -> 0.034504172 | G351: =AVERAGE(F352) -> 0.043040618 | H351: 1 | I351: 0.47006399 | J351: =INTERCEPT($G$168:G350,$I$168:I350) -> -0.0053733322 | K351: =SLOPE($G$168:G350,$I$168:I350) -> 0.018682162 | L351: =J351+K351*I351 -> 0.0034084796 | M351: =AVERAGE($G$168:G350) -> -0.00070132007 | N351: =(L351-G351)^2 -> 0.0015707064 | O351: =(M351-G351)^2 -> 0.0019133571 | P351: =1-AVERAGE($N$348:N351)/AVERAGE($O$348:O351) -> 0.024023659 | Q351: =O351-N351+(M351-L351)^2 -> 0.00035954121
A352: 29372 | B352: 111.24 | C352: 5.89333 | D352: =LN((B352+C352/12)/B351) -> 0.049923953 | E352: 0.0068833355 | F352: =D352-E352 -> 0.043040618 | G352: =AVERAGE(F353) -> 0.025226138 | H352: 1 | I352: 0.16900205 | J352: =INTERCEPT($G$168:G351,$I$168:I351) -> -0.0054018997 | K352: =SLOPE($G$168:G351,$I$168:I351) -> 0.019653052 | L352: =J352+K352*I352 -> -0.0020804936 | M352: =AVERAGE($G$168:G351) -> -0.00046359215 | N352: =(L352-G352)^2 -> 0.00074565215 | O352: =(M352-G352)^2 -> 0.00065996225 | P352: =1-AVERAGE($N$348:N352)/AVERAGE($O$348:O352) -> 0.01804218 | Q352: =O352-N352+(M352-L352)^2 -> -8.3075525e-05
A353: 29402 | B353: 114.24 | C353: 5.94 | D353: =LN((B353+C353/12)/B352) -> 0.030935093 | E353: 0.0057089543 | F353: =D353-E353 -> 0.025226138 | G353: =AVERAGE(F354) -> 0.060620039 | H353: 1 | I353: 0.11167739 | J353: =INTERCEPT($G$168:G352,$I$168:I352) -> -0.0051915895 | K353: =SLOPE($G$168:G352,$I$168:I352) -> 0.019403054 | L353: =J353+K353*I353 -> -0.003024707 | M353: =AVERAGE($G$168:G352) -> -0.00032472874 | N353: =(L353-G353)^2 -> 0.0040506537 | O353: =(M353-G353)^2 -> 0.0037142648 | P353: =1-AVERAGE($N$348:N353)/AVERAGE($O$348:O353) -> -0.0014545551 | Q353: =O353-N353+(M353-L353)^2 -> -0.0003290991
A354: 29433 | B354: 121.67 | C354: 5.98333 | D354: =LN((B354+C354/12)/B353) -> 0.067100652 | E354: 0.0064806124 | F354: =D354-E354 -> 0.060620039 | G354: =AVERAGE(F355) -> 0.0026065135 | H354: 1 | I354: 0.12445526 | J354: =INTERCEPT($G$168:G353,$I$168:I353) -> -0.0046034749 | K354: =SLOPE($G$168:G353,$I$168:I353) -> 0.018419621 | L354: =J354+K354*I354 -> -0.0023110562 | M354: =AVERAGE($G$168:G353) -> 2.9313007e-06 | N354: =(L354-G354)^2 -> 2.4182492e-05 | O354: =(M354-G354)^2 -> 6.7786405e-06 | P354: =1-AVERAGE($N$348:N354)/AVERAGE($O$348:O354) -> -0.0022949441 | Q354: =O354-N354+(M354-L354)^2 -> -1.2049313e-05
A355: 29464 | B355: 122.38 | C355: 6.02667 | D355: =LN((B355+C355/12)/B354) -> 0.0099138869 | E355: 0.0073073733 | F355: =D355-E355 -> 0.0026065135 | G355: =AVERAGE(F356) -> 0.020699678 | H355: 0 | I355: 0.14289084 | J355: =INTERCEPT($G$168:G354,$I$168:I354) -> -0.0045600977 | K355: =SLOPE($G$168:G354,$I$168:I354) -> 0.018351139 | L355: =J355+K355*I355 -> -0.0019378881 | M355: =AVERAGE($G$168:G354) -> 1.68542e-05 | N355: =(L355-G355)^2 -> 0.0005124594 | O355: =(M355-G355)^2 -> 0.0004277792 | P355: =1-AVERAGE($N$348:N355)/AVERAGE($O$348:O355) -> -0.0062569408 | Q355: =O355-N355+(M355-L355)^2 -> -8.0859182e-05
A356: 29494 | B356: 125.46 | C356: 6.07 | D356: =LN((B356+C356/12)/B355) -> 0.028879763 | E356: 0.0081800854 | F356: =D356-E356 -> 0.020699678 | G356: =AVERAGE(F357) -> 0.010671086 | H356: 0 | I356: 0.17987075 | J356: =INTERCEPT($G$168:G355,$I$168:I355) -> -0.0043732508 | K356: =SLOPE($G$168:G355,$I$168:I355) -> 0.018084166 | L356: =J356+K356*I356 -> -0.0011204383 | M356: =AVERAGE($G$168:G355) -> 0.00012686922 | N356: =(L356-G356)^2 -> 0.00013904004 | O356: =(M356-G356)^2 -> 0.0001111805 | P356: =1-AVERAGE($N$348:N356)/AVERAGE($O$348:O356) -> -0.0075360536 | Q356: =O356-N356+(M356-L356)^2 -> -2.6303761e-05
A357: 29525 | B357: 127.47 | C357: 6.1 | D357: =LN((B357+C357/12)/B356) -> 0.019874013 | E357: 0.0092029272 | F357: =D357-E357 -> 0.010671086 | G357: =AVERAGE(F358) -> 0.090318421 | H357: 0 | I357: 0.23750813 | J357: =INTERCEPT($G$168:G356,$I$168:I356) -> -0.0042884989 | K357: =SLOPE($G$168:G356,$I$168:I356) -> 0.017994167 | L357: =J357+K357*I357 -> -1.4738019e-05 | M357: =AVERAGE($G$168:G356) -> 0.00018265873 | N357: =(L357-G357)^2 -> 0.0081600796 | O357: =(M357-G357)^2 -> 0.0081244556 | P357: =1-AVERAGE($N$348:N357)/AVERAGE($O$348:O357) -> -0.0066640674 | Q357: =O357-N357+(M357-L357)^2 -> -3.5585012e-05
A358: 29555 | B358: 140.52 | C358: 6.13 | D358: =LN((B358+C358/12)/B357) -> 0.10109752 | E358: 0.0107791 | F358: =D358-E358 -> 0.090318421 | G358: =AVERAGE(F359) -> -0.042760675 | H358: 0 | I358: 0.4089479 | J358: =INTERCEPT($G$168:G357,$I$168:I357) -> -0.0037858189 | K358: =SLOPE($G$168:G357,$I$168:I357) -> 0.017884505 | L358: =J358+K358*I358 -> 0.0035280117 | M358: =AVERAGE($G$168:G357) -> 0.00065705747 | N358: =(L358-G358)^2 -> 0.0021426425 | O358: =(M358-G358)^2 -> 0.0018850995 | P358: =1-AVERAGE($N$348:N358)/AVERAGE($O$348:O358) -> -0.014504434 | Q358: =O358-N358+(M358-L358)^2 -> -0.00024930064
A359: 29586 | B359: 135.75999 | C359: 6.16 | D359: =LN((B359+C359/12)/B358) -> -0.030687225 | E359: 0.012073449 | F359: =D359-E359 -> -0.042760675 | G359: =AVERAGE(F360) -> -0.054570996 | H359: 0 | I359: 0.60537383 | J359: =INTERCEPT($G$168:G358,$I$168:I358) -> -0.0038237805 | K359: =SLOPE($G$168:G358,$I$168:I358) -> 0.01706453 | L359: =J359+K359*I359 -> 0.0065066395 | M359: =AVERAGE($G$168:G358) -> 0.0004297395 | N359: =(L359-G359)^2 -> 0.0037304775 | O359: =(M359-G359)^2 -> 0.0030250809 | P359: =1-AVERAGE($N$348:N359)/AVERAGE($O$348:O359) -> -0.033806959 | Q359: =O359-N359+(M359-L359)^2 -> -0.00066846793
...

Sheet M1_h3
A1: date | B1: sp500_price | C1: D_12m | D1: sp500_log_total_return | E1: rfree | F1: log_equity_prem | G1: fwd_avg_log_eqprem (Y) | H1: usrec | I1: p_M1_h3 | J1: alpha | K1: beta | L1: forecast | M1: benchmark | N1: se_model | O1: se_benchmark | P1: rolling_R2_OS | Q1: clark_west_f
A2: 18718 | B2: 21.48 | C2: 1.52 | E2: 0.0011592468 | G2: =AVERAGE(F3:F5) -> -0.0034570368 | H2: 0
A3: 18748 | B3: 22.43 | C3: 1.53333 | D3: =LN((B3+C3/12)/B2) -> 0.048957672 | E3: 0.0012168233 | F3: =D3-E3 -> 0.047740849 | G3: =AVERAGE(F4:F6) -> 0.0042599535 | H3: 0
A4: 18779 | B4: 21.52 | C4: 1.54667 | D4: =LN((B4+C4/12)/B3) -> -0.035445197 | E4: 0.0012825803 | F4: =D4-E4 -> -0.036727777 | G4: =AVERAGE(F5:F7) -> 0.030724995 | H4: 0
A5: 18809 | B5: 20.959999 | C5: 1.56 | D5: =LN((B5+C5/12)/B4) -> -0.020183805 | E5: 0.0012003766 | F5: =D5-E5 -> -0.021384182 | G5: =AVERAGE(F6:F8) -> 0.038927431 | H5: 0
A6: 18840 | B6: 22.4 | C6: 1.54667 | D6: =LN((B6+C6/12)/B5) -> 0.072182616 | E6: 0.0012907966 | F6: =D6-E6 -> 0.070891819 | G6: =AVERAGE(F7:F9) -> 0.012045688 | H6: 0
A7: 18871 | B7: 23.280001 | C7: 1.53333 | D7: =LN((B7+C7/12)/B6) -> 0.044007426 | E7: 0.0013400788 | F7: =D7-E7 -> 0.042667348 | G7: =AVERAGE(F8:F10) -> -0.0017282897 | H7: 0
A8: 18901 | B8: 23.26 | C8: 1.52 | D8: =LN((B8+C8/12)/B7) -> 0.0045714168 | E8: 0.0013482899 | F8: =D8-E8 -> 0.0032231269 | G8: =AVERAGE(F9:F11) -> 0.011084614 | H8: 0
A9: 18932 | B9: 22.940001 | C9: 1.48333 | D9: =LN((B9+C9/12)/B8) -> -0.0084790469 | E9: 0.0012743633 | F9: =D9-E9 -> -0.0097534102 | G9: =AVERAGE(F10:F12) -> 0.020673734 | H9: 0
A10: 18962 | B10: 22.879999 | C10: 1.44667 | D10: =LN((B10+C10/12)/B9) -> 0.0026362108 | E10: 0.0012907966 | F10: =D10-E10 -> 0.0013454142 | G10: =AVERAGE(F11:F13) -> 0.0091096806 | H10: 0
A11: 18993 | B11: 23.77 | C11: 1.41 | D11: =LN((B11+C11/12)/B10) -> 0.043092199 | E11: 0.0014303602 | F11: =D11-E11 -> 0.041661839 | G11: =AVERAGE(F12:F14) -> 0.011937818 | H11: 0
A12: 19024 | B12: 24.139999 | C12: 1.41333 | D12: =LN((B12+C12/12)/B11) -> 0.020312962 | E12: 0.0012990121 | F12: =D12-E12 -> 0.01901395 | G12: =AVERAGE(F13:F15) -> -0.0078146705 | H12: 0
A13: 19053 | B13: 23.26 | C13: 1.41667 | D13: =LN((B13+C13/12)/B12) -> -0.032072383 | E13: 0.0012743633 | F13: =D13-E13 -> -0.033346746 | G13: =AVERAGE(F14:F16) -> 0.012143478 | H13: 0
A14: 19084 | B14: 24.370001 | C14: 1.42 | D14: =LN((B14+C14/12)/B13) -> 0.051461691 | E14: 0.001315441 | F14: =D14-E14 -> 0.05014625 | G14: =AVERAGE(F15:F17) -> 0.011592967 | H14: 0
... A167: 23742 | B167: 84.75 | C167: 2.5 | D167: =LN((B167+C167/12)/B166) -> 0.0063566216 | E167: 0.0031450242 | F167: =D167-E167 -> 0.0032115974 | G167: =AVERAGE(F168:F170) -> 0.0047373017 | H167: 0
A168: 23773 | B168: 87.559998 | C168: 2.51667 | D168: =LN((B168+C168/12)/B167) -> 0.035010821 | E168: 0.0031208697 | F168: =D168-E168 -> 0.031889951 | G168: =AVERAGE(F169:F171) -> 0.005056837 | H168: 0 | I168: 0.2366131
A169: 23801 | B169: 87.43 | C169: 2.53333 | D169: =LN((B169+C169/12)/B168) -> 0.00092594832 | E169: 0.003217449 | F169: =D169-E169 -> -0.0022915007 | G169: =AVERAGE(F170:F172) -> 0.0029804569 | H169: 0 | I169: 0.23467296
A170: 23832 | B170: 86.160004 | C170: 2.55 | D170: =LN((B170+C170/12)/B169) -> -0.012169096 | E170: 0.003217449 | F170: =D170-E170 -> -0.015386545 | G170: =AVERAGE(F171:F173) -> -0.0086854767 | H170: 0 | I170: 0.23305953
A171: 23862 | B171: 89.110001 | C171: 2.57 | D171: =LN((B171+C171/12)/B170) -> 0.036066006 | E171: 0.003217449 | F171: =D171-E171 -> 0.032848557 | G171: =AVERAGE(F172:F174) -> -0.015380651 | H171: 0 | I171: 0.23163529
A172: 23893 | B172: 88.419998 | C172: 2.59 | D172: =LN((B172+C172/12)/B171) -> -0.0053353739 | E172: 0.0031852673 | F172: =D172-E172 -> -0.0085206412 | G172: =AVERAGE(F173:F175) -> -0.0053234798 | H172: 0 | I172: 0.23021299
A173: 23923 | B173: 84.120003 | C173: 2.61 | D173: =LN((B173+C173/12)/B172) -> -0.047271529 | E173: 0.0031128168 | F173: =D173-E173 -> -0.050384346 | G173: =AVERAGE(F174:F176) -> 0.021723477 | H173: 0 | I173: 0.22867203
A174: 23954 | B174: 85.25 | C174: 2.62667 | D174: =LN((B174+C174/12)/B173) -> 0.015908057 | E174: 0.0031450242 | F174: =D174-E174 -> 0.012763033 | G174: =AVERAGE(F175:F177) -> 0.026167135 | H174: 0 | I174: 0.2262752
A175: 23985 | B175: 87.169998 | C175: 2.64333 | D175: =LN((B175+C175/12)/B174) -> 0.024795898 | E175: 0.0031450242 | F175: =D175-E175 -> 0.021650874 | G175: =AVERAGE(F176:F178) -> 0.015718192 | H175: 0 | I175: 0.223675
A176: 24015 | B176: 89.959999 | C176: 2.66 | D176: =LN((B176+C176/12)/B175) -> 0.03396593 | E176: 0.0032094047 | F176: =D176-E176 -> 0.030756526 | G176: =AVERAGE(F177:F179) -> 0.0080599347 | H176: 0 | I176: 0.22069764
A177: 24046 | B177: 92.419998 | C177: 2.68 | D177: =LN((B177+C177/12)/B176) -> 0.029391858 | E177: 0.0032978538 | F177: =D177-E177 -> 0.026094004 | G177: =AVERAGE(F178:F180) -> 0.0005503468 | H177: 0 | I177: 0.21692996
A178: 24076 | B178: 91.610001 | C178: 2.7 | D178: =LN((B178+C178/12)/B177) -> -0.0063498904 | E178: 0.0033460626 | F178: =D178-E178 -> -0.009695953 | G178: =AVERAGE(F179:F181) -> -0.0026545712 | H178: 0 | I178: 0.21384611
A179: 24107 | B179: 92.43 | C179: 2.72 | D179: =LN((B179+C179/12)/B178) -> 0.011360466 | E179: 0.0035787134 | F179: =D179-E179 -> 0.0077817528 | G179: =AVERAGE(F180:F182) -> -0.0129854 | H179: 0 | I179: 0.20825986
... A347: 29220 | B347: 107.94 | C347: 5.65 | D347: =LN((B347+C347/12)/B346) -> 0.020980621 | E347: 0.0095188323 | F347: =D347-E347 -> 0.011461788 | G347: =AVERAGE(F348:F350) -> -0.024707055 | H347: 0 | I347: 0.58215409
A348: 29251 | B348: 114.16 | C348: 5.7 | D348: =LN((B348+C348/12)/B347) -> 0.06017766 | E348: 0.0094887929 | F348: =D348-E348 -> 0.050688867 | G348: =AVERAGE(F349:F351) -> -0.030101953 | H348: 0 | I348: 0.42768812 | J348: =INTERCEPT($G$168:G345,$I$168:I345) -> -0.0041004748 | K348: =SLOPE($G$168:G345,$I$168:I345) -> 0.02107739 | L348: =J348+K348*I348 -> 0.0049140746 | M348: =AVERAGE($G$168:G345) -> -0.0003875976 | N348: =(L348-G348)^2 -> 0.0012261222 | O348: =(M348-G348)^2 -> 0.00088294292 | P348: =1-AVERAGE($N$348:N348)/AVERAGE($O$348:O348) -> -0.38867662 | Q348: =O348-N348+(M348-L348)^2 -> -0.00031507154
A349: 29280 | B349: 113.66 | C349: 5.75 | D349: =LN((B349+C349/12)/B348) -> -0.00018250906 | E349: 0.010132483 | F349: =D349-E349 -> -0.010314992 | G349: =AVERAGE(F350:F352) -> -0.01231675 | H349: 1 | I349: 0.44904758 | J349: =INTERCEPT($G$168:G346,$I$168:I346) -> -0.0045774528 | K349: =SLOPE($G$168:G346,$I$168:I346) -> 0.024061256 | L349: =J349+K349*I349 -> 0.0062271961 | M349: =AVERAGE($G$168:G346) -> -0.00028890401 | N349: =(L349-G349)^2 -> 0.00034387793 | O349: =(M349-G349)^2 -> 0.00014466907 | P349: =1-AVERAGE($N$348:N349)/AVERAGE($O$348:O349) -> -0.52781413 | Q349: =O349-N349+(M349-L349)^2 -> -0.00015674929
A350: 29311 | B350: 102.09 | C350: 5.8 | D350: =LN((B350+C350/12)/B349) -> -0.10263361 | E350: 0.011861426 | F350: =D350-E350 -> -0.11449504 | G350: =AVERAGE(F351:F353) -> 0.034256976 | H350: 1 | I350: 0.71039917 | J350: =INTERCEPT($G$168:G347,$I$168:I347) -> -0.0029745522 | K350: =SLOPE($G$168:G347,$I$168:I347) -> 0.014129053 | L350: =J350+K350*I350 -> 0.0070627151 | M350: =AVERAGE($G$168:G347) -> -0.00042456041 | N350: =(L350-G350)^2 -> 0.00073952784 | O350: =(M350-G350)^2 -> 0.001202809 | P350: =1-AVERAGE($N$348:N350)/AVERAGE($O$348:O350) -> -0.035467288 | Q350: =O350-N350+(M350-L350)^2 -> 0.00051934044
A351: 29341 | B351: 106.29 | C351: 5.84667 | D351: =LN((B351+C351/12)/B350) -> 0.044889899 | E351: 0.010385726 | F351: =D351-E351 -> 0.034504172 | G351: =AVERAGE(F352:F354) -> 0.042962265 | H351: 1 | I351: 0.66339712 | J351: =INTERCEPT($G$168:G348,$I$168:I348) -> -0.0021289839 | K351: =SLOPE($G$168:G348,$I$168:I348) -> 0.0084713077 | L351: =J351+K351*I351 -> 0.0034908573 | M351: =AVERAGE($G$168:G348) -> -0.0005885239 | N351: =(L351-G351)^2 -> 0.001557992 | O351: =(M351-G351)^2 -> 0.0018966712 | P351: =1-AVERAGE($N$348:N351)/AVERAGE($O$348:O351) -> 0.062894695 | Q351: =O351-N351+(M351-L351)^2 -> 0.00035532054
A352: 29372 | B352: 111.24 | C352: 5.89333 | D352: =LN((B352+C352/12)/B351) -> 0.049923953 | E352: 0.0068833355 | F352: =D352-E352 -> 0.043040618 | G352: =AVERAGE(F353:F355) -> 0.02948423 | H352: 1 | I352: 0.11899655 | J352: =INTERCEPT($G$168:G349,$I$168:I349) -> -0.0017551848 | K352: =SLOPE($G$168:G349,$I$168:I349) -> 0.0060127912 | L352: =J352+K352*I352 -> -0.0010396834 | M352: =AVERAGE($G$168:G349) -> -0.0006529647 | N352: =(L352-G352)^2 -> 0.00093170931 | O352: =(M352-G352)^2 -> 0.00090825053 | P352: =1-AVERAGE($N$348:N352)/AVERAGE($O$348:O352) -> 0.046891231 | Q352: =O352-N352+(M352-L352)^2 -> -2.3309235e-05
A353: 29402 | B353: 114.24 | C353: 5.94 | D353: =LN((B353+C353/12)/B352) -> 0.030935093 | E353: 0.0057089543 | F353: =D353-E353 -> 0.025226138 | G353: =AVERAGE(F354:F356) -> 0.02797541 | H353: 1 | I353: 0.050283687 | J353: =INTERCEPT($G$168:G350,$I$168:I350) -> -0.0033137808 | K353: =SLOPE($G$168:G350,$I$168:I350) -> 0.015315203 | L353: =J353+K353*I353 -> -0.0025436759 | M353: =AVERAGE($G$168:G350) -> -0.0004622 | N353: =(L353-G353)^2 -> 0.00093141462 | O353: =(M353-G353)^2 -> 0.00080869768 | P353: =1-AVERAGE($N$348:N353)/AVERAGE($O$348:O353) -> 0.01940378 | Q353: =O353-N353+(M353-L353)^2 -> -0.0001183844
A354: 29433 | B354: 121.67 | C354: 5.98333 | D354: =LN((B354+C354/12)/B353) -> 0.067100652 | E354: 0.0064806124 | F354: =D354-E354 -> 0.060620039 | G354: =AVERAGE(F355:F357) -> 0.011325759 | H354: 1 | I354: 0.063203411 | J354: =INTERCEPT($G$168:G351,$I$168:I351) -> -0.0047233495 | K354: =SLOPE($G$168:G351,$I$168:I351) -> 0.023821388 | L354: =J354+K354*I354 -> -0.0032177565 | M354: =AVERAGE($G$168:G351) -> -0.00022619747 | N354: =(L354-G354)^2 -> 0.00021151385 | O354: =(M354-G354)^2 -> 0.0001334477 | P354: =1-AVERAGE($N$348:N354)/AVERAGE($O$348:O354) -> 0.0059105646 | Q354: =O354-N354+(M354-L354)^2 -> -6.9116721e-05
A355: 29464 | B355: 122.38 | C355: 6.02667 | D355: =LN((B355+C355/12)/B354) -> 0.0099138869 | E355: 0.0073073733 | F355: =D355-E355 -> 0.0026065135 | G355: =AVERAGE(F356:F358) -> 0.040563061 | H355: 0 | I355: 0.084604196 | J355: =INTERCEPT($G$168:G352,$I$168:I352) -> -0.0043506477 | K355: =SLOPE($G$168:G352,$I$168:I352) -> 0.022743316 | L355: =J355+K355*I355 -> -0.0024264677 | M355: =AVERAGE($G$168:G352) -> -6.5600564e-05 | N355: =(L355-G355)^2 -> 0.0018480996 | O355: =(M355-G355)^2 -> 0.0016506882 | P355: =1-AVERAGE($N$348:N355)/AVERAGE($O$348:O355) -> -0.021247688 | Q355: =O355-N355+(M355-L355)^2 -> -0.00019183775
A356: 29494 | B356: 125.46 | C356: 6.07 | D356: =LN((B356+C356/12)/B355) -> 0.028879763 | E356: 0.0081800854 | F356: =D356-E356 -> 0.020699678 | G356: =AVERAGE(F357:F359) -> 0.019409611 | H356: 0 | I356: 0.13326286 | J356: =INTERCEPT($G$168:G353,$I$168:I353) -> -0.0037887034 | K356: =SLOPE($G$168:G353,$I$168:I353) -> 0.020642265 | L356: =J356+K356*I356 -> -0.0010378562 | M356: =AVERAGE($G$168:G353) -> 8.5157558e-05 | N356: =(L356-G356)^2 -> 0.0004180989 | O356: =(M356-G356)^2 -> 0.00037343448 | P356: =1-AVERAGE($N$348:N356)/AVERAGE($O$348:O356) -> -0.025837988 | Q356: =O356-N356+(M356-L356)^2 -> -4.3403252e-05
A357: 29525 | B357: 127.47 | C357: 6.1 | D357: =LN((B357+C357/12)/B356) -> 0.019874013 | E357: 0.0092029272 | F357: =D357-E357 -> 0.010671086 | G357: =AVERAGE(F358:F360) -> -0.0023377499 | H357: 0 | I357: 0.22044015 | J357: =INTERCEPT($G$168:G354,$I$168:I354) -> -0.0035592335 | K357: =SLOPE($G$168:G354,$I$168:I354) -> 0.019810073 | L357: =J357+K357*I357 -> 0.00080770192 | M357: =AVERAGE($G$168:G354) -> 0.00014526773 | N357: =(L357-G357)^2 -> 9.8938673e-06 | O357: =(M357-G357)^2 -> 6.1653766e-06 | P357: =1-AVERAGE($N$348:N357)/AVERAGE($O$348:O357) -> -0.026283703 | Q357: =O357-N357+(M357-L357)^2 -> -3.2896716e-06
A358: 29555 | B358: 140.52 | C358: 6.13 | D358: =LN((B358+C358/12)/B357) -> 0.10109752 | E358: 0.0107791 | F358: =D358-E358 -> 0.090318421 | G358: =AVERAGE(F359:F361) -> -0.030583218 | H358: 0 | I358: 0.51414163 | J358: =INTERCEPT($G$168:G355,$I$168:I355) -> -0.0029430538 | K358: =SLOPE($G$168:G355,$I$168:I355) -> 0.017716275 | L358: =J358+K358*I358 -> 0.0061656209 | M358: =AVERAGE($G$168:G355) -> 0.00036025599 | N358: =(L358-G358)^2 -> 0.0013504771 | O358: =(M358-G358)^2 -> 0.00095749857 | P358: =1-AVERAGE($N$348:N358)/AVERAGE($O$348:O358) -> -0.067309994 | Q358: =O358-N358+(M358-L358)^2 -> -0.00035927631
A359: 29586 | B359: 135.75999 | C359: 6.16 | D359: =LN((B359+C359/12)/B358) -> -0.030687225 | E359: 0.012073449 | F359: =D359-E359 -> -0.042760675 | G359: =AVERAGE(F360:F362) -> -0.0067514666 | H359: 0 | I359: 0.78898993 | J359: =INTERCEPT($G$168:G356,$I$168:I356) -> -0.0027420288 | K359: =SLOPE($G$168:G356,$I$168:I356) -> 0.017204667 | L359: =J359+K359*I359 -> 0.01083228 | M359: =AVERAGE($G$168:G356) -> 0.00046104623 | N359: =(L359-G359)^2 -> 0.00030918815 | O359: =(M359-G359)^2 -> 5.2020341e-05 | P359: =1-AVERAGE($N$348:N359)/AVERAGE($O$348:O359) -> -0.095441081 | Q359: =O359-N359+(M359-L359)^2 -> -0.00014960531
...

Sheet M2_h3
A1: date | B1: sp500_price | C1: D_12m | D1: sp500_log_total_return | E1: rfree | F1: log_equity_prem | G1: fwd_avg_log_eqprem (Y) | H1: usrec | I1: p_M2_h3 | J1: alpha | K1: beta | L1: forecast | M1: benchmark | N1: se_model | O1: se_benchmark | P1: rolling_R2_OS | Q1: clark_west_f
A2: 18718 | B2: 21.48 | C2: 1.52 | E2: 0.0011592468 | G2: =AVERAGE(F3:F5) -> -0.0034570368 | H2: 0
A3: 18748 | B3: 22.43 | C3: 1.53333 | D3: =LN((B3+C3/12)/B2) -> 0.048957672 | E3: 0.0012168233 | F3: =D3-E3 -> 0.047740849 | G3: =AVERAGE(F4:F6) -> 0.0042599535 | H3: 0
A4: 18779 | B4: 21.52 | C4: 1.54667 | D4: =LN((B4+C4/12)/B3) -> -0.035445197 | E4: 0.0012825803 | F4: =D4-E4 -> -0.036727777 | G4: =AVERAGE(F5:F7) -> 0.030724995 | H4: 0
A5: 18809 | B5: 20.959999 | C5: 1.56 | D5: =LN((B5+C5/12)/B4) -> -0.020183805 | E5: 0.0012003766 | F5: =D5-E5 -> -0.021384182 | G5: =AVERAGE(F6:F8) -> 0.038927431 | H5: 0
A6: 18840 | B6: 22.4 | C6: 1.54667 | D6: =LN((B6+C6/12)/B5) -> 0.072182616 | E6: 0.0012907966 | F6: =D6-E6 -> 0.070891819 | G6: =AVERAGE(F7:F9) -> 0.012045688 | H6: 0
A7: 18871 | B7: 23.280001 | C7: 1.53333 | D7: =LN((B7+C7/12)/B6) -> 0.044007426 | E7: 0.0013400788 | F7: =D7-E7 -> 0.042667348 | G7: =AVERAGE(F8:F10) -> -0.0017282897 | H7: 0
A8: 18901 | B8: 23.26 | C8: 1.52 | D8: =LN((B8+C8/12)/B7) -> 0.0045714168 | E8: 0.0013482899 | F8: =D8-E8 -> 0.0032231269 | G8: =AVERAGE(F9:F11) -> 0.011084614 | H8: 0
A9: 18932 | B9: 22.940001 | C9: 1.48333 | D9: =LN((B9+C9/12)/B8) -> -0.0084790469 | E9: 0.0012743633 | F9: =D9-E9 -> -0.0097534102 | G9: =AVERAGE(F10:F12) -> 0.020673734 | H9: 0
A10: 18962 | B10: 22.879999 | C10: 1.44667 | D10: =LN((B10+C10/12)/B9) -> 0.0026362108 | E10: 0.0012907966 | F10: =D10-E10 -> 0.0013454142 | G10: =AVERAGE(F11:F13) -> 0.0091096806 | H10: 0
A11: 18993 | B11: 23.77 | C11: 1.41 | D11: =LN((B11+C11/12)/B10) -> 0.043092199 | E11: 0.0014303602 | F11: =D11-E11 -> 0.041661839 | G11: =AVERAGE(F12:F14) -> 0.011937818 | H11: 0
A12: 19024 | B12: 24.139999 | C12: 1.41333 | D12: =LN((B12+C12/12)/B11) -> 0.020312962 | E12: 0.0012990121 | F12: =D12-E12 -> 0.01901395 | G12: =AVERAGE(F13:F15) -> -0.0078146705 | H12: 0
A13: 19053 | B13: 23.26 | C13: 1.41667 | D13: =LN((B13+C13/12)/B12) -> -0.032072383 | E13: 0.0012743633 | F13: =D13-E13 -> -0.033346746 | G13: =AVERAGE(F14:F16) -> 0.012143478 | H13: 0
A14: 19084 | B14: 24.370001 | C14: 1.42 | D14: =LN((B14+C14/12)/B13) -> 0.051461691 | E14: 0.001315441 | F14: =D14-E14 -> 0.05014625 | G14: =AVERAGE(F15:F17) -> 0.011592967 | H14: 0
... A167: 23742 | B167: 84.75 | C167: 2.5 | D167: =LN((B167+C167/12)/B166) -> 0.0063566216 | E167: 0.0031450242 | F167: =D167-E167 -> 0.0032115974 | G167: =AVERAGE(F168:F170) -> 0.0047373017 | H167: 0
A168: 23773 | B168: 87.559998 | C168: 2.51667 | D168: =LN((B168+C168/12)/B167) -> 0.035010821 | E168: 0.0031208697 | F168: =D168-E168 -> 0.031889951 | G168: =AVERAGE(F169:F171) -> 0.005056837 | H168: 0 | I168: 0.25697584
A169: 23801 | B169: 87.43 | C169: 2.53333 | D169: =LN((B169+C169/12)/B168) -> 0.00092594832 | E169: 0.003217449 | F169: =D169-E169 -> -0.0022915007 | G169: =AVERAGE(F170:F172) -> 0.0029804569 | H169: 0 | I169: 0.25075938
A170: 23832 | B170: 86.160004 | C170: 2.55 | D170: =LN((B170+C170/12)/B169) -> -0.012169096 | E170: 0.003217449 | F170: =D170-E170 -> -0.015386545 | G170: =AVERAGE(F171:F173) -> -0.0086854767 | H170: 0 | I170: 0.27349241
A171: 23862 | B171: 89.110001 | C171: 2.57 | D171: =LN((B171+C171/12)/B170) -> 0.036066006 | E171: 0.003217449 | F171: =D171-E171 -> 0.032848557 | G171: =AVERAGE(F172:F174) -> -0.015380651 | H171: 0 | I171: 0.29506458
A172: 23893 | B172: 88.419998 | C172: 2.59 | D172: =LN((B172+C172/12)/B171) -> -0.0053353739 | E172: 0.0031852673 | F172: =D172-E172 -> -0.0085206412 | G172: =AVERAGE(F173:F175) -> -0.0053234798 | H172: 0 | I172: 0.3381707
A173: 23923 | B173: 84.120003 | C173: 2.61 | D173: =LN((B173+C173/12)/B172) -> -0.047271529 | E173: 0.0031128168 | F173: =D173-E173 -> -0.050384346 | G173: =AVERAGE(F174:F176) -> 0.021723477 | H173: 0 | I173: 0.47749319
